<?xml version="1.0"?>

<robot xmlns:sensor="http://playerstage.sourceforge.net/gazebo/xmlschema/#sensor"
       xmlns:controller="http://playerstage.sourceforge.net/gazebo/xmlschema/#controller"
       xmlns:interface="http://playerstage.sourceforge.net/gazebo/xmlschema/#interface"
       xmlns:xacro="http://www.ros.org/wiki/xacro">

  <!-- <xacro:include filename="$(find new_wheelchair)/urdf/wheelchair.gazebo.xacro" /> -->
  <!-- <xacro:include filename="$(find new_wheelchair)/urdf/wheelchair.transmission.xacro" /> -->
  <!-- <xacro:include filename="$(find new_wheelchair)/urdf/wheelchair.constants.xacro" /> -->


  <property name="M_PI" value="3.14" />


<!-- =============================================================================== -->


  <!-- Original Testing Macro for front wheels only -->
  <xacro:macro name="f_wheel" >

    <joint name="wheel_joint" type="continuous">
      <axis xyz="0 1 0" />
      <limit effort="100" velocity="100" />
      <dynamics damping="0.0" friction="0.05" />
      <origin xyz="0 0.15 0" rpy="${M_PI} 0 0" />
      <parent link="wheelchair_base_link" />
      <child link="base_f_wheel_link" />
    </joint>

    <link name="base_f_wheel_link" >

      <visual>

        <geometry>
          <mesh filename="package://new_wheelchair/meshes/front_wheel.dae" />
        </geometry>
      </visual>
      
    </link>

  </xacro:macro>


  <!-- Original Testing Macro for wheelchair_base (includes front & caster wheels and wheelchair body) -->
  <xacro:macro name="wheelchair_base" >

    <link name="base_footprint" >
      <visual>
        <origin xyz="0 0 0" rpy="0 0 0" />
        <geometry>
          <box size="0.01 0.01 0.01" />
        </geometry>
      </visual>
    </link>

    <joint name="base_footprint_joint" type="fixed" >
      <origin xyz="0 0 0.17" rpy="0 0 0" />
      <child link="wheelchair_base_link" />
      <parent link="base_footprint" />
    </joint>

    <link name="wheelchair_base_link" >
      <visual>
        <origin xyz="0 0 0" rpy="0 0 0" />
        <geometry>
          <box size="0.4 0.3 0.05" />
        </geometry>
      </visual>
    </link>

    

    <xacro:f_wheel >
    </xacro:f_wheel>

  </xacro:macro>

<!-- =============================================================================== -->




</robot>